<mujoco>
  <compiler meshdir="cars/meshes" />
  <asset>
    <mesh name="buddy_mushr_base_nano" file="mushr_base_nano.stl"/>
    <mesh name="buddy_mushr_wheel" file="mushr_wheel.stl"/>
    <mesh name="buddy_mushr_ydlidar" file="mushr_ydlidar.stl"/>
  </asset>
  <default>
      <default class="buddy_wheel">
      <geom fitscale="1.2" type="ellipsoid" friction="2 0.005 0.0001" contype="1" conaffinity="0" mesh="buddy_mushr_wheel" mass="0.498952"/>
    </default>
    <default class="buddy_throttle">
      <joint type="hinge" axis="0 1 0" frictionloss="0.001" damping="0.01" armature="0.01" limited="false"/>
    </default>
    <default class="buddy_throttle_r">
      <joint type="hinge" axis="0 1 0" frictionloss="0.001" damping="0.01" armature="0.01" limited="false"/>
    </default>
  </default>
  <worldbody>
    <body name="buddy" pos="0.0 2.0 0.3" euler="0 -1.5 0.0">
      <camera name="buddy_third_person" mode="fixed" pos="-1 0 1" xyaxes="0 -1 0 0.707 0 0.707"/>
      <joint type="free"/>

      <camera name="buddy_realsense_d435i" mode="fixed" pos="-0.005 0 .165" euler="0 4.712 4.712"/>
      <site name="buddy_imu" pos="-0.005 0 .165"/>

      <geom pos="0 0 0.094655" type="mesh" mass="0.542137" mesh="buddy_mushr_base_nano"/>
      <geom name="buddy_realsense_d435i" size="0.012525 0.045 0.0125" pos="0.0123949 0 0.162178" mass="0.072" type="box"/>
      <geom name="buddy_ydlidar" pos="-0.035325 0 0.202405" type="mesh" mass="0.180" mesh="buddy_mushr_ydlidar"/>

      <body name="buddy_steering_wheel" pos="0.1385 0 0.0488">
        <geom class="buddy_wheel" contype="0" conaffinity="0" mass="0.01" rgba="0 0 0 0.01"/>
      </body>

      <body name="buddy_wheel_bl" pos="-0.258 0.115 0.0748">
        <joint class="buddy_throttle" name="buddy_wheel_bl_throttle"/>
        <geom class="buddy_wheel"/>
        <geom class="buddy_wheel" type="mesh" contype="0" conaffinity="0" group="1" rgba="1 1 1 0.3"/>
      </body>
      <body name="buddy_wheel_br" pos="-0.258 -0.115 0.0748">
        <joint class="buddy_throttle_r" name="buddy_wheel_br_throttle"/>
        <geom class="buddy_wheel"/>
        <geom class="buddy_wheel" type="mesh" contype="0" conaffinity="0" group="1" rgba="1 1 1 0.3"/>
      </body>
    </body>
  </worldbody>
  <actuator>
    <velocity kv="100" gear="0.04" forcelimited="true" forcerange="-500 500" name="buddy_throttle_velocity" tendon="buddy_throttle"/>
    <velocity kv="100" gear="0.04" forcelimited="true" forcerange="-500 500" name="buddy_throttle_velocity_r" tendon="buddy_throttle_r"/>
  </actuator>
  <tendon>
    <fixed name="buddy_throttle">
      <joint joint="buddy_wheel_bl_throttle" coef="0.25"/>
    </fixed>
    <fixed name="buddy_throttle_r">
      <joint joint="buddy_wheel_br_throttle" coef="0.25"/>
    </fixed>
  </tendon>
  <sensor>
    <accelerometer name="buddy_accelerometer" site="buddy_imu" />
    <gyro name="buddy_gyro" site="buddy_imu" />
    <velocimeter name="buddy_velocimeter" site="buddy_imu" />
  </sensor>
</mujoco>
